Kotlin のコルーチンでは、エラーハンドリングは非同期処理を扱う上で非常に重要です。
コルーチン内で発生した例外を適切に処理しないと、**プログラムがクラッシュ** したり、**予期しない挙動** を引き起こしたりする可能性があります。
ここでは、コルーチン内でのエラーハンドリングの方法について詳しく紹介します。

------

## **1. コルーチンでのエラーハンドリングの基本**

コルーチン内でエラーが発生した場合、その例外は通常、**コルーチンの親（親スコープ）に伝播** します。
`try-catch` 構文を使うことで、コルーチン内で発生した例外を捕捉できます。

### **例：`try-catch` でコルーチンのエラーを捕捉**

```
import kotlinx.coroutines.*

fun main() = runBlocking {
    launch {
        try {
            // ここで例外が発生する可能性がある
            delay(1000)
            throw Exception("Something went wrong!")
        } catch (e: Exception) {
            println("Caught exception: ${e.message}")
        }
    }

    println("Coroutine launched")
}
```

出力:

```
python


CopyEdit
Coroutine launched
Caught exception: Something went wrong!
```

🔹 **ポイント**

- コルーチン内でエラーが発生した場合、`try-catch` で捕捉して適切に処理できます。
- `Exception` は一般的な例外型ですが、特定の例外クラスを使うことでさらに細かくエラーハンドリングが可能です。

------

## **2. `SupervisorJob` と `supervisorScope` を使ったエラー管理**

通常、1つの子コルーチンでエラーが発生すると、**親コルーチンとその他の子コルーチンもキャンセルされます**。
しかし、`SupervisorJob` や `supervisorScope` を使うと、**1つの子コルーチンのエラーが他の子コルーチンに影響しないようにできる**。

### **例：`supervisorScope` の使用**

```
import kotlinx.coroutines.*

fun main() = runBlocking {
    supervisorScope {
        launch {
            delay(500)
            throw Exception("Child coroutine failed")
        }

        launch {
            delay(1000)
            println("This coroutine is still running")
        }
    }
    println("All coroutines finished")
}
```

出力:

```
This coroutine is still running
All coroutines finished
```

🔹 **ポイント**

- `supervisorScope` 内で発生したエラーは、**他の子コルーチンには影響を与えません**。
- エラーが発生しても、他の処理は継続できます。

------

## **3. `CoroutineExceptionHandler` を使ったグローバルなエラーハンドリング**

`CoroutineExceptionHandler` を使うと、**非同期タスクで発生した未処理の例外を捕捉** できます。
これは、コルーチンが親スコープやエラーハンドリングの方法を持たない場合に有効です。

### **例：`CoroutineExceptionHandler` を使ったエラーハンドリング**

```
import kotlinx.coroutines.*

fun main() = runBlocking {
    // コルーチンのエラーハンドリング用ハンドラー
    val handler = CoroutineExceptionHandler { _, exception ->
        println("Caught exception: ${exception.message}")
    }

    // `CoroutineExceptionHandler` を指定してコルーチンを起動
    val job = GlobalScope.launch(handler) {
        delay(1000)
        throw Exception("Error in coroutine")
    }

    job.join()  // コルーチンが終了するのを待つ
    println("Main thread continues")
}
```

出力:

```
Caught exception: Error in coroutine
Main thread continues
```

🔹 **ポイント**

- `CoroutineExceptionHandler` は **全てのコルーチン内で未捕捉の例外を処理** できます。
- 主に **グローバルなエラーハンドリング** に使います。

------

## **4. 非同期タスクのエラーハンドリング**

非同期タスクを扱う `async` で例外が発生した場合、その例外は `Deferred` オブジェクトに伝播します。
`await()` を使うことで、例外を再度捕捉できます。

### **例：`async` と `await()` のエラーハンドリング**

```
import kotlinx.coroutines.*

fun main() = runBlocking {
    val deferred = async {
        delay(1000)
        throw Exception("Error in async")
    }

    try {
        deferred.await()  // エラーが発生するとここで例外がスローされる
    } catch (e: Exception) {
        println("Caught exception in async: ${e.message}")
    }
}
```

出力:

```
Caught exception in async: Error in async
```

🔹 **ポイント**

- `async` で返された `Deferred` オブジェクトは **`await()` で結果を取得** する際に例外をスローします。
- 例外を捕捉したい場合は、`await()` を `try-catch` で囲みます。

------

## **5. `isActive` を使ったキャンセル処理**

コルーチンが **キャンセルされたかどうかを確認** するには、`isActive` を使います。
キャンセルされた場合、例外が発生しますが、`isActive` を使って適切に管理できます。

### **例：`isActive` を使ってキャンセルの管理**

```kotlin
import kotlinx.coroutines.*

fun main() = runBlocking {
    val job = launch {
        repeat(5) {
            if (!isActive) return@launch  // キャンセルされた場合に終了
            println("Working $it")
            delay(500)
        }
    }

    delay(1200)  // 少し待ってからキャンセル
    job.cancelAndJoin()  // コルーチンをキャンセル
    println("Coroutine cancelled")
}
```

出力:

```
Working 0
Working 1
Working 2
Working 3
Working 4
Coroutine cancelled
```

🔹 **ポイント**

- `isActive` を使用して、コルーチンが **キャンセルされたかどうか** を確認できます。
- キャンセルを適切に処理することで、**リソースの無駄遣いを防ぐ** ことができます。

------

## **6. まとめ**

コルーチンのエラーハンドリングは、非同期処理での失敗を管理するために非常に重要です。
以下の方法でエラーを適切に処理できます：

- **`try-catch`** を使ってコルーチン内で発生したエラーを捕捉する
- **`supervisorScope`** を使ってエラーが他のコルーチンに影響を与えないようにする
- **`CoroutineExceptionHandler`** でグローバルなエラーハンドリングを行う
- **`async` と `await()`** で非同期タスクのエラーを捕捉する
- **`isActive`** を使ってコルーチンのキャンセルを管理する

これらのテクニックを駆使して、Kotlin のコルーチンを使った非同期処理を **より堅牢でエラーに強い** ものにしましょう！